{"filename": "logger.py", "lineno": 28, "process": 35712, "message": "This is an info message", "taskName": null, "severity": "INFO", "timestamp": "2024-06-04 12:34:43,798"}
{"filename": "logger.py", "lineno": 31, "process": 35712, "message": "This is an error message", "taskName": null, "severity": "ERROR", "timestamp": "2024-06-04 12:34:43,798"}
{"filename": "logger.py", "lineno": 37, "process": 35712, "message": "This is a warning message", "taskName": null, "severity": "WARNING", "timestamp": "2024-06-04 12:34:43,798"}
{"filename": "logger.py", "lineno": 40, "process": 35712, "message": "This is a critical message", "taskName": null, "severity": "CRITICAL", "timestamp": "2024-06-04 12:34:43,798"}
{"filename": "logger.py", "lineno": 45, "process": 35712, "message": "This is an exception message", "exc_info": "Traceback (most recent call last):\n  File \"/home/fabio/Works/DataDashr/data-dashr/datadashr/utilities/logger.py\", line 56, in <module>\n    raise Exception(\"This is an exception message\")\nException: This is an exception message", "taskName": null, "severity": "ERROR", "timestamp": "2024-06-04 12:34:43,798"}
{"filename": "logger.py", "lineno": 28, "process": 35761, "message": "This is an info message", "taskName": null, "severity": "INFO", "timestamp": "2024-06-04 12:35:47,417"}
{"filename": "logger.py", "lineno": 31, "process": 35761, "message": "This is an error message", "taskName": null, "severity": "ERROR", "timestamp": "2024-06-04 12:35:47,417"}
{"filename": "logger.py", "lineno": 37, "process": 35761, "message": "This is a warning message", "taskName": null, "severity": "WARNING", "timestamp": "2024-06-04 12:35:47,417"}
{"filename": "logger.py", "lineno": 40, "process": 35761, "message": "This is a critical message", "taskName": null, "severity": "CRITICAL", "timestamp": "2024-06-04 12:35:47,417"}
{"filename": "logger.py", "lineno": 45, "process": 35761, "message": "This is an exception message", "exc_info": "Traceback (most recent call last):\n  File \"/home/fabio/Works/DataDashr/data-dashr/datadashr/utilities/logger.py\", line 56, in <module>\n    raise Exception(\"This is an exception message\")\nException: This is an exception message", "taskName": null, "severity": "ERROR", "timestamp": "2024-06-04 12:35:47,417"}
